Workbook

Sheet Assumptions
A1: CABBAGE PRODUCTION COSTS - Yi Family Example
A2: Assumptions and cost-function calibration. Updated August 2026.
A3: HOW TO USE: edit only the yellow-filled blue cells. The Cost Table and Per-Unit Costs tabs recalculate automatically.
A5: FARM SCALE
A6: Plot size (acres) | B6: 40 | C6: THE FIXED FACTOR. Fixed in the short run. | D6: Teaching assumption
A7: Benchmark yield (tons per acre) | B7: 21 | C7: 42,000 lb/acre. Used only to convert the source budget's per-acre figures into per-ton ones. | D7: UF/IFAS Aug 2025
A8: Benchmark output (tons) | B8: =B6*B7 -> 840 | C8: acres x yield
A10: FIXED COSTS (do not vary with output)
A11: Land rent ($ per acre per year) | B11: 221 | C11: Rented-land case. | D11: UF/IFAS Aug 2025
A12: Equipment & vehicle ownership ($ per acre per year) | B12: 370 | C12: $336 machinery + $34 vehicles. | D12: UF/IFAS Aug 2025
A13: Opportunity cost - foregone off-farm earnings ($ per year) | B13: 35980 | C13: Family labour charged at a full-time farm wage. | D13: BLS OOH, May 2024
A14: TOTAL FIXED COST (TFC) | B14: =B6*B11+B6*B12+B13 -> 59620 | C14: acres x (rent + equipment) + opportunity cost
A15: Acreage belongs HERE and nowhere else. The plot is the fixed factor, so its cost is fixed - it does not change when the farm produces more or fewer tons.
A17: VARIABLE COSTS (vary with TONS of cabbage, not with acreage)
A18: The source budget reports these per acre, so column B keeps the sourced figure for the audit trail. The model uses column C - dollars per TON - because tons are what
A19: actually drives these costs: no cabbage, no seed bill, no harvest bill. Column C = column B divided by the benchmark yield in B7. Acreage never enters variable cost.
A20: Input | B20: $ per acre (source) | C20: $ per ton (used) | D20: Source
A21: 1. Seeds & transplants | B21: 587 | C21: =B21/$B$7 -> 27.952381 | D21: UF/IFAS Aug 2025
A22: 2. Water / irrigation | B22: 170 | C22: =B22/$B$7 -> 8.0952381 | D22: UC ANR Ventura 2012/13
A23: 3. Fertilizer & lime | B23: 479 | C23: =B23/$B$7 -> 22.809524 | D23: UF/IFAS Aug 2025
A24: 4. Pesticides & pest control | B24: 361 | C24: =B24/$B$7 -> 17.190476 | D24: UF/IFAS Aug 2025
A25: 5. Harvest & packing | B25: 4805 | C25: =B25/$B$7 -> 228.80952 | D25: UF/IFAS Aug 2025
A26: TOTAL VARIABLE COST PER TON at benchmark intensity | B26: =SUM(B21:B25) -> 6402 | C26: =SUM(C21:C25) -> 304.85714 | D26: This is AVC at the benchmark output.
A27: Total variable cost at benchmark output ($) | B27: =C26*B8 -> 256080 | D27: $ per ton x tons. No acreage term anywhere in this line.
A29: VARIABLE COST FUNCTION TVC = a x Q + b x Q^2 so AVC = a + b x Q
A30: Harvest & packing is charged per box, so on its own it would stay flat per ton. The four agronomic inputs go onto a FIXED plot, so squeezing more tons out of it runs into
A31: diminishing returns - each extra ton needs disproportionately more seed, water and spray. That is what makes b positive and marginal cost rise.
A32: CALIBRATION MODE (type 1, 2 or 3) | B32: 3 | C32: Mode 3 is the default. ALL THREE modes give identical total cost - and identical profit - AT the benchmark output. | D32: See note below
A33: MODE 1 harvest & packing strictly flat per ton. Cleanest cost accounting; almost no curvature (15% of TVC) and the benchmark is nowhere near the optimum.
A34: MODE 2 fit so marginal cost equals the NET price at the benchmark. Moderate curvature (46%); 21 tons/acre is exactly the profit-maximising output.
A35: MODE 3 choose the curvature directly in B39. At b = 0.2 - the coefficient the original slide used - curvature reaches 62% of TVC and marginal cost at the benchmark comes
A36: out at $472.86, within 14 cents of the gross F.O.B. price of $473. In every mode 'a' then follows from AVC = a + bQ, so sourced spending at 840 tons is matched exactly - until the presentation rounding below is switched on, which trades a little accuracy for round numbers.
A37: a1 - harvest & packing per ton ($ per ton) | B37: =C25 -> 228.80952 | C37: Straight from the table above - already per ton.
A38: a2 - linear agronomic cost per ton ($ per ton) | B38: 40 | C38: MODE 1 ONLY. Agronomic cost per ton before crowding. | D38: Calibration choice
A39: b - chosen curvature ($ per ton squared) | B39: 0.2 | C39: MODE 3 ONLY. Raise it for a more visibly bent curve; 0.2 matches the original slide. | D39: Design choice
A40: Calibration net price ($ per ton) | B40: 425.7 | C40: MODE 2 ONLY. The price at which the farm was observed choosing 21 t/acre. | D40: UF/IFAS Aug 2025
A41: Keep the calibration price FIXED. It anchors the shape of the curve in mode 2. The scenario price further down is separate, so you can vary price and watch output respond.
A42: a under mode 1 | B42: =B37+B38 -> 268.80952 | C42: a1 + a2
A43: b under mode 1 | B43: =(C26-B42)/B8 -> 0.042913832 | C43: From AVC = a + bQ at the benchmark.
A44: a under mode 2 | B44: =2*C26-B40 -> 184.01429 | C44: Solves AVC = a + bQ and MC = calibration price, both at the benchmark.
...

Sheet Cost Table
A1: CABBAGE PRODUCTION COSTS
A2: Yi Family Example - quantity in tons
A3: Copy A5:D17 into PowerPoint to replace the table image on the slide.
A5: Q | B5: TC | C5: TFC | D5: TVC
A6: 50 | B6: =C6+D6 -> 67250 | C6: =Assumptions!$B$65 -> 60000 | D6: =Assumptions!$B$66*A6+Assumptions!$B$67*A6^2 -> 7250
A7: 100 | B7: =C7+D7 -> 75500 | C7: =Assumptions!$B$65 -> 60000 | D7: =Assumptions!$B$66*A7+Assumptions!$B$67*A7^2 -> 15500
A8: 200 | B8: =C8+D8 -> 95000 | C8: =Assumptions!$B$65 -> 60000 | D8: =Assumptions!$B$66*A8+Assumptions!$B$67*A8^2 -> 35000
A9: 300 | B9: =C9+D9 -> 118500 | C9: =Assumptions!$B$65 -> 60000 | D9: =Assumptions!$B$66*A9+Assumptions!$B$67*A9^2 -> 58500
A10: 400 | B10: =C10+D10 -> 146000 | C10: =Assumptions!$B$65 -> 60000 | D10: =Assumptions!$B$66*A10+Assumptions!$B$67*A10^2 -> 86000
A11: 500 | B11: =C11+D11 -> 177500 | C11: =Assumptions!$B$65 -> 60000 | D11: =Assumptions!$B$66*A11+Assumptions!$B$67*A11^2 -> 117500
A12: 600 | B12: =C12+D12 -> 213000 | C12: =Assumptions!$B$65 -> 60000 | D12: =Assumptions!$B$66*A12+Assumptions!$B$67*A12^2 -> 153000
A13: 700 | B13: =C13+D13 -> 252500 | C13: =Assumptions!$B$65 -> 60000 | D13: =Assumptions!$B$66*A13+Assumptions!$B$67*A13^2 -> 192500
A14: 800 | B14: =C14+D14 -> 296000 | C14: =Assumptions!$B$65 -> 60000 | D14: =Assumptions!$B$66*A14+Assumptions!$B$67*A14^2 -> 236000
A15: 900 | B15: =C15+D15 -> 343500 | C15: =Assumptions!$B$65 -> 60000 | D15: =Assumptions!$B$66*A15+Assumptions!$B$67*A15^2 -> 283500
A16: 1000 | B16: =C16+D16 -> 395000 | C16: =Assumptions!$B$65 -> 60000 | D16: =Assumptions!$B$66*A16+Assumptions!$B$67*A16^2 -> 335000
A17: 1100 | B17: =C17+D17 -> 450500 | C17: =Assumptions!$B$65 -> 60000 | D17: =Assumptions!$B$66*A17+Assumptions!$B$67*A17^2 -> 390500
A19: Q = tons of cabbage per season. TC = total cost. TFC = total fixed cost. TVC = total variable cost. All dollars per season.
A20: Fixed: land rent, equipment, opportunity cost of the family's labor. Variable: seeds, water, fertilizer, pesticides, harvest & packing.
A21: Sources: UF/IFAS NE Florida cabbage budget (Aug 2025); BLS OOH May 2024 (opportunity cost); USDA NASS Vegetables 2025 & Cash Rents 2025; UC ANR Ventura 2012/13. Full detail on the Sources tab.

Sheet Per-Unit Costs
A1: PER-UNIT COSTS
A2: Derived from the Cost Table. Nothing to edit here.
A4: Q (tons) | B4: AFC ($/ton) | C4: AVC ($/ton) | D4: ATC ($/ton) | E4: MC ($/ton, smooth) | F4: MC ($/ton, discrete)
A5: ='Cost Table'!A6 -> 50 | B5: ='Cost Table'!C6/'Cost Table'!A6 -> 1200 | C5: ='Cost Table'!D6/'Cost Table'!A6 -> 145 | D5: ='Cost Table'!B6/'Cost Table'!A6 -> 1345 | E5: =Assumptions!$B$66+2*Assumptions!$B$67*A5 -> 155 | F5: n/a
A6: ='Cost Table'!A7 -> 100 | B6: ='Cost Table'!C7/'Cost Table'!A7 -> 600 | C6: ='Cost Table'!D7/'Cost Table'!A7 -> 155 | D6: ='Cost Table'!B7/'Cost Table'!A7 -> 755 | E6: =Assumptions!$B$66+2*Assumptions!$B$67*A6 -> 175 | F6: =('Cost Table'!B7-'Cost Table'!B6)/('Cost Table'!A7-'Cost Table'!A6) -> 165
A7: ='Cost Table'!A8 -> 200 | B7: ='Cost Table'!C8/'Cost Table'!A8 -> 300 | C7: ='Cost Table'!D8/'Cost Table'!A8 -> 175 | D7: ='Cost Table'!B8/'Cost Table'!A8 -> 475 | E7: =Assumptions!$B$66+2*Assumptions!$B$67*A7 -> 215 | F7: =('Cost Table'!B8-'Cost Table'!B7)/('Cost Table'!A8-'Cost Table'!A7) -> 195
A8: ='Cost Table'!A9 -> 300 | B8: ='Cost Table'!C9/'Cost Table'!A9 -> 200 | C8: ='Cost Table'!D9/'Cost Table'!A9 -> 195 | D8: ='Cost Table'!B9/'Cost Table'!A9 -> 395 | E8: =Assumptions!$B$66+2*Assumptions!$B$67*A8 -> 255 | F8: =('Cost Table'!B9-'Cost Table'!B8)/('Cost Table'!A9-'Cost Table'!A8) -> 235
A9: ='Cost Table'!A10 -> 400 | B9: ='Cost Table'!C10/'Cost Table'!A10 -> 150 | C9: ='Cost Table'!D10/'Cost Table'!A10 -> 215 | D9: ='Cost Table'!B10/'Cost Table'!A10 -> 365 | E9: =Assumptions!$B$66+2*Assumptions!$B$67*A9 -> 295 | F9: =('Cost Table'!B10-'Cost Table'!B9)/('Cost Table'!A10-'Cost Table'!A9) -> 275
A10: ='Cost Table'!A11 -> 500 | B10: ='Cost Table'!C11/'Cost Table'!A11 -> 120 | C10: ='Cost Table'!D11/'Cost Table'!A11 -> 235 | D10: ='Cost Table'!B11/'Cost Table'!A11 -> 355 | E10: =Assumptions!$B$66+2*Assumptions!$B$67*A10 -> 335 | F10: =('Cost Table'!B11-'Cost Table'!B10)/('Cost Table'!A11-'Cost Table'!A10) -> 315
A11: ='Cost Table'!A12 -> 600 | B11: ='Cost Table'!C12/'Cost Table'!A12 -> 100 | C11: ='Cost Table'!D12/'Cost Table'!A12 -> 255 | D11: ='Cost Table'!B12/'Cost Table'!A12 -> 355 | E11: =Assumptions!$B$66+2*Assumptions!$B$67*A11 -> 375 | F11: =('Cost Table'!B12-'Cost Table'!B11)/('Cost Table'!A12-'Cost Table'!A11) -> 355
A12: ='Cost Table'!A13 -> 700 | B12: ='Cost Table'!C13/'Cost Table'!A13 -> 85.714286 | C12: ='Cost Table'!D13/'Cost Table'!A13 -> 275 | D12: ='Cost Table'!B13/'Cost Table'!A13 -> 360.71429 | E12: =Assumptions!$B$66+2*Assumptions!$B$67*A12 -> 415 | F12: =('Cost Table'!B13-'Cost Table'!B12)/('Cost Table'!A13-'Cost Table'!A12) -> 395
A13: ='Cost Table'!A14 -> 800 | B13: ='Cost Table'!C14/'Cost Table'!A14 -> 75 | C13: ='Cost Table'!D14/'Cost Table'!A14 -> 295 | D13: ='Cost Table'!B14/'Cost Table'!A14 -> 370 | E13: =Assumptions!$B$66+2*Assumptions!$B$67*A13 -> 455 | F13: =('Cost Table'!B14-'Cost Table'!B13)/('Cost Table'!A14-'Cost Table'!A13) -> 435
A14: ='Cost Table'!A15 -> 900 | B14: ='Cost Table'!C15/'Cost Table'!A15 -> 66.666667 | C14: ='Cost Table'!D15/'Cost Table'!A15 -> 315 | D14: ='Cost Table'!B15/'Cost Table'!A15 -> 381.66667 | E14: =Assumptions!$B$66+2*Assumptions!$B$67*A14 -> 495 | F14: =('Cost Table'!B15-'Cost Table'!B14)/('Cost Table'!A15-'Cost Table'!A14) -> 475
A15: ='Cost Table'!A16 -> 1000 | B15: ='Cost Table'!C16/'Cost Table'!A16 -> 60 | C15: ='Cost Table'!D16/'Cost Table'!A16 -> 335 | D15: ='Cost Table'!B16/'Cost Table'!A16 -> 395 | E15: =Assumptions!$B$66+2*Assumptions!$B$67*A15 -> 535 | F15: =('Cost Table'!B16-'Cost Table'!B15)/('Cost Table'!A16-'Cost Table'!A15) -> 515
A16: ='Cost Table'!A17 -> 1100 | B16: ='Cost Table'!C17/'Cost Table'!A17 -> 54.545455 | C16: ='Cost Table'!D17/'Cost Table'!A17 -> 355 | D16: ='Cost Table'!B17/'Cost Table'!A17 -> 409.54545 | E16: =Assumptions!$B$66+2*Assumptions!$B$67*A16 -> 575 | F16: =('Cost Table'!B17-'Cost Table'!B16)/('Cost Table'!A17-'Cost Table'!A16) -> 555
A18: AFC = TFC/Q. AVC = TVC/Q. ATC = TC/Q. Smooth MC = a + 2bQ (the derivative of TVC). Discrete MC = change in TC divided by change in Q between rows.
A19: The two MC columns differ because the Q steps are wide; the discrete version is the average marginal cost across each interval.
H28: ATC bottoms out at about $369 per ton near 644 tons (16.1 t/acre), where the MC curve crosses it. MC then keeps rising and meets the $425.70 net price at 840 tons - the profit-maximising output. Rows below 300 tons are omitted from the chart only, because AFC is so large there that ATC swamps the other curves; the full range is in the table at left.

Sheet Current Prices
A1: CURRENT MARKET PRICES
A2: USDA AMS National FOB Review, 18 August 2026. These are GROWER-LEVEL FOB quotes - what the farm actually receives.
A3: Paste any figure from the '$/ton' columns into cell B38 on the Assumptions tab to re-run the whole model against that price.
A5: ATC at benchmark output ($ per ton) | B5: =Assumptions!$B$65/Assumptions!$B$8+Assumptions!$B$66+Assumptions!$B$67*Assumptions!$B$8 -> 374.42857 | C5: The break-even price. Anything above this earns a profit.
A6: Broker fee deducted from F.O.B. | B6: =Assumptions!$B$78 -> 0.1 | C6: From the Assumptions tab.
A7: Benchmark yield (tons per acre) | B7: =Assumptions!$B$7 -> 21 | C7: Used to convert profit per ton into profit per acre.
A9: Origin | B9: Variety / pack | C9: Pack (lb) | D9: FOB low ($/pkg) | E9: FOB high ($/pkg) | F9: FOB low ($/ton) | G9: FOB high ($/ton) | H9: Net low ($/ton) | I9: Net high ($/ton) | J9: Profit/acre at low | K9: Profit/acre at high | L9: Profitable at the low end?
A10: Central Coast California | B10: Round green, cartons | C10: 45 | D10: 10.45 | E10: 15 | F10: =D10*2000/C10 -> 464.44444 | G10: =E10*2000/C10 -> 666.66667 | H10: =F10*(1-$B$6) -> 418 | I10: =G10*(1-$B$6) -> 600 | J10: =(H10-$B$5)*$B$7 -> 915 | K10: =(I10-$B$5)*$B$7 -> 4737 | L10: =IF(J10>0,"Yes","No") -> Yes
A11: Central Coast California | B11: Red, cartons | C11: 45 | D11: 14.45 | E11: 18.55 | F11: =D11*2000/C11 -> 642.22222 | G11: =E11*2000/C11 -> 824.44444 | H11: =F11*(1-$B$6) -> 578 | I11: =G11*(1-$B$6) -> 742 | J11: =(H11-$B$5)*$B$7 -> 4275 | K11: =(I11-$B$5)*$B$7 -> 7719 | L11: =IF(J11>0,"Yes","No") -> Yes
A12: Mexico crossings via Texas | B12: Round green, cartons | C12: 50 | D12: 14 | E12: 16 | F12: =D12*2000/C12 -> 560 | G12: =E12*2000/C12 -> 640 | H12: =F12*(1-$B$6) -> 504 | I12: =G12*(1-$B$6) -> 576 | J12: =(H12-$B$5)*$B$7 -> 2721 | K12: =(I12-$B$5)*$B$7 -> 4233 | L12: =IF(J12>0,"Yes","No") -> Yes
A13: Mexico crossings via Texas | B13: Round green, sacks | C13: 50 | D13: 10 | E13: 12 | F13: =D13*2000/C13 -> 400 | G13: =E13*2000/C13 -> 480 | H13: =F13*(1-$B$6) -> 360 | I13: =G13*(1-$B$6) -> 432 | J13: =(H13-$B$5)*$B$7 -> -303 | K13: =(I13-$B$5)*$B$7 -> 1209 | L13: =IF(J13>0,"Yes","No") -> No
A14: Michigan | B14: Round green, crates & cartons | C14: 50 | D14: 10 | E14: 12 | F14: =D14*2000/C14 -> 400 | G14: =E14*2000/C14 -> 480 | H14: =F14*(1-$B$6) -> 360 | I14: =G14*(1-$B$6) -> 432 | J14: =(H14-$B$5)*$B$7 -> -303 | K14: =(I14-$B$5)*$B$7 -> 1209 | L14: =IF(J14>0,"Yes","No") -> No
A15: New York | B15: Round green, cartons | C15: 50 | D15: 7 | E15: 9 | F15: =D15*2000/C15 -> 280 | G15: =E15*2000/C15 -> 360 | H15: =F15*(1-$B$6) -> 252 | I15: =G15*(1-$B$6) -> 324 | J15: =(H15-$B$5)*$B$7 -> -2571 | K15: =(I15-$B$5)*$B$7 -> -1059 | L15: =IF(J15>0,"Yes","No") -> No
A16: New York | B16: Round green, sacks | C16: 50 | D16: 6 | E16: 7 | F16: =D16*2000/C16 -> 240 | G16: =E16*2000/C16 -> 280 | H16: =F16*(1-$B$6) -> 216 | I16: =G16*(1-$B$6) -> 252 | J16: =(H16-$B$5)*$B$7 -> -3327 | K16: =(I16-$B$5)*$B$7 -> -2571 | L16: =IF(J16>0,"Yes","No") -> No
A17: South & Central California | B17: Round green, ORGANIC, cartons | C17: 45 | D17: 18 | E17: 26 | F17: =D17*2000/C17 -> 800 | G17: =E17*2000/C17 -> 1155.5556 | H17: =F17*(1-$B$6) -> 720 | I17: =G17*(1-$B$6) -> 1040 | J17: =(H17-$B$5)*$B$7 -> 7257 | K17: =(I17-$B$5)*$B$7 -> 13977 | L17: =IF(J17>0,"Yes","No") -> Yes
A18: South & Central California | B18: Red, ORGANIC, cartons | C18: 45 | D18: 20 | E18: 26 | F18: =D18*2000/C18 -> 888.88889 | G18: =E18*2000/C18 -> 1155.5556 | H18: =F18*(1-$B$6) -> 800 | I18: =G18*(1-$B$6) -> 1040 | J18: =(H18-$B$5)*$B$7 -> 8937 | K18: =(I18-$B$5)*$B$7 -> 13977 | L18: =IF(J18>0,"Yes","No") -> Yes
A19: UF/IFAS budget figure (Aug 2025) | B19: Round green, boxes | C19: 50 | D19: 11.83 | E19: 11.83 | F19: =D19*2000/C19 -> 473.2 | G19: =E19*2000/C19 -> 473.2 | H19: =F19*(1-$B$6) -> 425.88 | I19: =G19*(1-$B$6) -> 425.88 | J19: =(H19-$B$5)*$B$7 -> 1080.48 | K19: =(I19-$B$5)*$B$7 -> 1080.48 | L19: =IF(J19>0,"Yes","No") -> Yes
A21: WHOLESALE TERMINAL PRICE - DO NOT USE AS FARM REVENUE
A22: Los Angeles terminal market, 18 August 2026, Central Coast round green, 50-lb cartons: $19.00-20.00 per carton, i.e. $760-$800 per ton. That is what a Los Angeles
A23: BUYER pays. It includes freight, cooling and the wholesaler's margin, none of which reaches the grower. Using it as the farm's price roughly doubles apparent revenue.
A25: SEASONAL NOTE
A26: Florida is absent from the August FOB review because cabbage there is a winter and spring crop. The cost side of this model is a Florida budget, so a student checking
A27: the price against a Florida source in August will find nothing. Central Coast California is the relevant origin at this time of year.
A29: TEACHING NOTE FOR THE PRICE-TAKER SLIDE
A30: Same cabbage, same week, same cost structure - and the farm-gate price ranges from $280 per ton in New York to over $1,100 per ton for organic California. A price taker
A31: influences none of it. The 'Profitable at the low end?' column shows which origins clear this farm's break-even cost of about $376 per ton.

Sheet TC Curve
A1: TOTAL COST FUNCTION
A2: ="TC = "&TEXT(Assumptions!B65,"#,##0")&" + "&TEXT(Assumptions!B66,"0.00")&"Q + "&TEXT(Assumptions!B67,"0.0000")&"Q²" -> TC = 60,000 + 135.00Q + 0.2000Q²
A3: The dotted line is the fitted quadratic. The markers are the Cost Table values with a small deviation applied, so they read as observations scattered around a fitted
A4: curve rather than as a perfect formula. THE COST TABLE ITSELF STAYS EXACT - the noise lives only in column G on this sheet and affects nothing but the chart.
A5: For comparison, the original slide used TC = 30,000 + 40Q + 0.2Q² and did the same thing: an exact table, with visibly scattered points on the chart.
A7: Q (tons) | B7: Fitted TC ($) | D7: Noise scale | E7: 1.5 | F7: Set to 0 to plot the exact quadratic; 2 to double the scatter.
A8: 0 | B8: =Assumptions!$B$65+Assumptions!$B$66*A8+Assumptions!$B$67*A8^2 -> 60000
A9: 25 | B9: =Assumptions!$B$65+Assumptions!$B$66*A9+Assumptions!$B$67*A9^2 -> 63500 | D9: Q (tons) | E9: Exact TC ($) | F9: Deviation | G9: Plotted TC ($)
A10: 50 | B10: =Assumptions!$B$65+Assumptions!$B$66*A10+Assumptions!$B$67*A10^2 -> 67250 | D10: ='Cost Table'!A6 -> 50 | E10: ='Cost Table'!B6 -> 67250 | F10: 0.0055 | G10: =E10*(1+$E$7*F10) -> 67804.812
A11: 75 | B11: =Assumptions!$B$65+Assumptions!$B$66*A11+Assumptions!$B$67*A11^2 -> 71250 | D11: ='Cost Table'!A7 -> 100 | E11: ='Cost Table'!B7 -> 75500 | F11: -0.0341 | G11: =E11*(1+$E$7*F11) -> 71638.175
A12: 100 | B12: =Assumptions!$B$65+Assumptions!$B$66*A12+Assumptions!$B$67*A12^2 -> 75500 | D12: ='Cost Table'!A8 -> 200 | E12: ='Cost Table'!B8 -> 95000 | F12: 0.0317 | G12: =E12*(1+$E$7*F12) -> 99517.25
A13: 125 | B13: =Assumptions!$B$65+Assumptions!$B$66*A13+Assumptions!$B$67*A13^2 -> 80000 | D13: ='Cost Table'!A9 -> 300 | E13: ='Cost Table'!B9 -> 118500 | F13: -0.0048 | G13: =E13*(1+$E$7*F13) -> 117646.8
A14: 150 | B14: =Assumptions!$B$65+Assumptions!$B$66*A14+Assumptions!$B$67*A14^2 -> 84750 | D14: ='Cost Table'!A10 -> 400 | E14: ='Cost Table'!B10 -> 146000 | F14: -0.0236 | G14: =E14*(1+$E$7*F14) -> 140831.6
A15: 175 | B15: =Assumptions!$B$65+Assumptions!$B$66*A15+Assumptions!$B$67*A15^2 -> 89750 | D15: ='Cost Table'!A11 -> 500 | E15: ='Cost Table'!B11 -> 177500 | F15: -0.0029 | G15: =E15*(1+$E$7*F15) -> 176727.88
A16: 200 | B16: =Assumptions!$B$65+Assumptions!$B$66*A16+Assumptions!$B$67*A16^2 -> 95000 | D16: ='Cost Table'!A12 -> 600 | E16: ='Cost Table'!B12 -> 213000 | F16: 0.0264 | G16: =E16*(1+$E$7*F16) -> 221434.8
A17: 225 | B17: =Assumptions!$B$65+Assumptions!$B$66*A17+Assumptions!$B$67*A17^2 -> 100500 | D17: ='Cost Table'!A13 -> 700 | E17: ='Cost Table'!B13 -> 252500 | F17: 0.0343 | G17: =E17*(1+$E$7*F17) -> 265491.12
A18: 250 | B18: =Assumptions!$B$65+Assumptions!$B$66*A18+Assumptions!$B$67*A18^2 -> 106250 | D18: ='Cost Table'!A14 -> 800 | E18: ='Cost Table'!B14 -> 296000 | F18: 0.002 | G18: =E18*(1+$E$7*F18) -> 296888
A19: 275 | B19: =Assumptions!$B$65+Assumptions!$B$66*A19+Assumptions!$B$67*A19^2 -> 112250 | D19: ='Cost Table'!A15 -> 900 | E19: ='Cost Table'!B15 -> 343500 | F19: 0.0029 | G19: =E19*(1+$E$7*F19) -> 344994.23
A20: 300 | B20: =Assumptions!$B$65+Assumptions!$B$66*A20+Assumptions!$B$67*A20^2 -> 118500 | D20: ='Cost Table'!A16 -> 1000 | E20: ='Cost Table'!B16 -> 395000 | F20: -0.0243 | G20: =E20*(1+$E$7*F20) -> 380602.25
A21: 325 | B21: =Assumptions!$B$65+Assumptions!$B$66*A21+Assumptions!$B$67*A21^2 -> 125000 | D21: ='Cost Table'!A17 -> 1100 | E21: ='Cost Table'!B17 -> 450500 | F21: -0.0334 | G21: =E21*(1+$E$7*F21) -> 427929.95
A22: 350 | B22: =Assumptions!$B$65+Assumptions!$B$66*A22+Assumptions!$B$67*A22^2 -> 131750
A23: 375 | B23: =Assumptions!$B$65+Assumptions!$B$66*A23+Assumptions!$B$67*A23^2 -> 138750 | D23: Deviations average 1.9% and never exceed 3.5%. They are chosen so plotted cost still rises at every step:
A24: 400 | B24: =Assumptions!$B$65+Assumptions!$B$66*A24+Assumptions!$B$67*A24^2 -> 146000 | D24: a dip would imply negative marginal cost. Worth knowing - the chart on the original slide DID dip, with the 100-ton
A25: 425 | B25: =Assumptions!$B$65+Assumptions!$B$66*A25+Assumptions!$B$67*A25^2 -> 153500 | D25: point plotted below the 50-ton point. A sharp student could have caught it.
A26: 450 | B26: =Assumptions!$B$65+Assumptions!$B$66*A26+Assumptions!$B$67*A26^2 -> 161250
A27: 475 | B27: =Assumptions!$B$65+Assumptions!$B$66*A27+Assumptions!$B$67*A27^2 -> 169250
A28: 500 | B28: =Assumptions!$B$65+Assumptions!$B$66*A28+Assumptions!$B$67*A28^2 -> 177500
A29: 525 | B29: =Assumptions!$B$65+Assumptions!$B$66*A29+Assumptions!$B$67*A29^2 -> 186000
A30: 550 | B30: =Assumptions!$B$65+Assumptions!$B$66*A30+Assumptions!$B$67*A30^2 -> 194750
A31: 575 | B31: =Assumptions!$B$65+Assumptions!$B$66*A31+Assumptions!$B$67*A31^2 -> 203750
A32: 600 | B32: =Assumptions!$B$65+Assumptions!$B$66*A32+Assumptions!$B$67*A32^2 -> 213000
A33: 625 | B33: =Assumptions!$B$65+Assumptions!$B$66*A33+Assumptions!$B$67*A33^2 -> 222500
A34: 650 | B34: =Assumptions!$B$65+Assumptions!$B$66*A34+Assumptions!$B$67*A34^2 -> 232250
A35: 675 | B35: =Assumptions!$B$65+Assumptions!$B$66*A35+Assumptions!$B$67*A35^2 -> 242250
A36: 700 | B36: =Assumptions!$B$65+Assumptions!$B$66*A36+Assumptions!$B$67*A36^2 -> 252500
A37: 725 | B37: =Assumptions!$B$65+Assumptions!$B$66*A37+Assumptions!$B$67*A37^2 -> 263000 | I37: READING THE CURVE
A38: 750 | B38: =Assumptions!$B$65+Assumptions!$B$66*A38+Assumptions!$B$67*A38^2 -> 273750 | I38: The intercept is TFC: at Q = 0 the farm still owes land rent, equipment costs and the family's foregone earnings.
A39: 775 | B39: =Assumptions!$B$65+Assumptions!$B$66*A39+Assumptions!$B$67*A39^2 -> 284750 | I39: The curve steepens as Q rises because the plot is fixed - each extra ton takes disproportionately more seed, water and spray. That rising slope IS marginal cost.
A40: 800 | B40: =Assumptions!$B$65+Assumptions!$B$66*A40+Assumptions!$B$67*A40^2 -> 296000 | I40: Under the default calibration (mode 3, b = 0.2) the quadratic term carries about 62% of variable cost at Q = 1,100. The original slide reached 85%, which it managed only by leaving harvest & packing out of variable cost altogether.
A41: 825 | B41: =Assumptions!$B$65+Assumptions!$B$66*A41+Assumptions!$B$67*A41^2 -> 307500 | I41: Raise b in cell B39 on the Assumptions tab for a more pronounced bend; switch B32 to 1 and the curve flattens to nearly a straight line.
...

Sheet Sources
A1: SOURCES
A2: Retrieved 19 August 2026.
A4: Source | B4: Published | C4: What it supplies | D4: URL
A5: UF/IFAS, Sample Costs and Returns for Producing Cabbage in Northeast Florida | B5: August 2025 | C5: Primary calibration: yield 21 tons/acre; seed $587, fertilizer $479, pesticides $361, machinery $336 and vehicle $34 ownership, land rent $221, harvest & packing $4,805 - all per acre; price $11.83 per 50-lb box | D5: https://svaec.ifas.ufl.edu/media/svaecifasufledu/docs/pdf/agribusiness/CabbageBudgetReport_2025-August.pdf
A6: UC ANR / UC Cooperative Extension, Sample Costs to Produce Cabbage, Ventura County | B6: 2012/13 | C6: The slide's original source. Supplies the irrigation water figure (12 acre-inches at $14.17 per acre-inch = $170/acre) and the historical Ventura land rent of $933/acre | D6: https://ucanr.edu/sites/Farm_Management/files/179212.pdf
A7: USDA NASS, Land Values and Cash Rents 2025 Summary | B7: August 2025 | C7: Cash rent benchmarks: US irrigated cropland $244/acre; California $483/acre | D7: https://www.nass.usda.gov/Publications/Highlights/2025/2025LandValuesCashRents_FINAL.pdf
A8: UC Merced Water Systems Management Lab, Understanding Water Rates in California Irrigation Districts | B8: December 2025 (data 2006-2024) | C8: Agricultural water rates by region: Sacramento Valley $43/AF, San Joaquin Valley $76/AF, Tulare Lake Basin $112/AF; statewide range $0-$1,000/AF | D8: https://wsm.ucmerced.edu/wp-content/uploads/2025/12/understanding_water_rate.pdf
A9: US Bureau of Labor Statistics, Occupational Outlook Handbook: Agricultural Workers | B9: May 2024 wage data | C9: THE OPPORTUNITY COST USED IN THIS MODEL: median annual wage $35,980 ($17.30/hour); farmworkers and labourers, crop/nursery/greenhouse $35,690; agricultural equipment operators $42,580 | D9: https://www.bls.gov/ooh/farming-fishing-and-forestry/agricultural-workers.htm
A10: US Bureau of Labor Statistics, Occupational Outlook Handbook: Farmers, Ranchers, and Other Agricultural Managers | B10: May 2024 wage data | C10: Rejected alternative opportunity-cost benchmark: median annual wage $87,980, lowest 10% under $51,700. At $87,980 the farm loses $253/acre at benchmark yield | D10: https://www.bls.gov/ooh/management/farmers-ranchers-and-other-agricultural-managers.htm
A11: USDA AMS Specialty Crops Market News, National FOB Review | B11: 18 August 2026 | C11: CURRENT grower-level prices on the Current Prices tab. Central Coast CA round green $10.45-15.00 per 45-lb carton; Michigan $10-12 per 50-lb carton; New York $7-9; Mexico via Texas $14-16; organic S/Central CA $18-26 | D11: https://www.ams.usda.gov/mnreports/fvdfob.pdf
A12: USDA AMS, Los Angeles Terminal Market Vegetables Prices | B12: 18 August 2026 | C12: Wholesale cross-check, flagged as NOT farm revenue: round green 50-lb cartons $19-20 ($760-800/ton), red $20-21, savoy $30-31 | D12: https://www.ams.usda.gov/mnreports/hc_fv020.pdf
A13: USDA NASS, Vegetables 2025 Summary | B13: February 2026 | C13: Plausibility checks on yield and price. Fresh-market cabbage yields: US 444.4 cwt/acre (22.2 tons), California 455.0 (22.8), Florida 435.0 (21.8), Wisconsin 640.0 (32.0), Texas 260.0 (13.0). Season-average prices: US $24.40/cwt ($488/ton), Florida $21.40/cwt ($428/ton) | D13: https://esmis.nal.usda.gov/sites/default/release-files/795772/vegean26.pdf
A15: FIFTH SLIDE IMAGE - HARVEST & PACKING
A16: The slide needs a fifth photo to match the fifth variable row. Licence-clear places to find one, in order of least friction:
A18: 1. USDA ARS Image Gallery - https://www.ars.usda.gov/oc/images/photos/ Search 'cabbage harvest'. Images are public domain unless marked otherwise. Requested credit:
A19: 'Photo courtesy of USDA Agricultural Research Service.' One restriction: the photo must not be used to imply ARS endorsement of any product, company or position.
A20: 2. USDA on Flickr - https://www.flickr.com/photos/usdagov/ Works by federal employees are generally public domain; check the licence shown on the individual photo page.
A21: 3. Wikimedia Commons - https://commons.wikimedia.org/wiki/Category:Cabbage_fields and Category:Agricultural_workers. Licences vary file by file, so check each one; many need
A22: attribution to the photographer under CC BY-SA.
A24: The three existing photos on the slide look like commercial stock, so if you already have a stock subscription, searching it for 'cabbage harvest crew' or 'vegetable
A25: packing line' will give the closest visual match to the current set.
A28: NOT USED
A29: Michigan Cabbage Cost of Production 2024 (MSU Extension) is a relevant recent budget but its server blocked automated retrieval. If you want a Midwest comparison, that report is the one to pull manually:
A30: https://www.canr.msu.edu/resources/michigan-cabbage-cost-of-production-2024
